#VRML_SIM R2023b utf8

EXTERNPROTO "https://raw.githubusercontent.com/cyberbotics/webots/R2023b/projects/objects/floors/protos/Floor.proto"
EXTERNPROTO "https://raw.githubusercontent.com/cyberbotics/webots/R2023b/projects/objects/trees/protos/Forest.proto"
EXTERNPROTO "https://raw.githubusercontent.com/cyberbotics/webots/R2023b/projects/appearances/protos/OldSteel.proto"
EXTERNPROTO "https://raw.githubusercontent.com/cyberbotics/webots/R2023b/projects/objects/backgrounds/protos/TexturedBackground.proto"
EXTERNPROTO "https://raw.githubusercontent.com/cyberbotics/webots/R2023b/projects/objects/backgrounds/protos/TexturedBackgroundLight.proto"

WorldInfo {
}
Viewpoint {
  orientation -0.30424812056377437 0.0018334749785961304 0.9525910557542066 3.1301209714759026
  position 11.876332478738373 -6.520506132749908 9.786217029821447
}
TexturedBackground {
}
TexturedBackgroundLight {
}
Robot {
  translation -0.000558664853831465 -3.070909231970435 0.17182047064524367
  rotation 0.9759784382716044 -0.21724826838925868 -0.01640968953968481 0.006324365899383245
  children [
    DEF base_torso Shape {
      appearance OldSteel {
      }
      geometry Box {
        size 0.8 0.3 0.1
      }
    }
    DEF rightLeg1 HingeJoint {
      jointParameters HingeJointParameters {
        position 0.9824095603973166
        anchor 0.31 -0.18 0
      }
      device [
        RotationalMotor {
          name "rightLegVertical1"
        }
      ]
      endPoint Solid {
        translation 0.31 -0.18 0
        rotation -1.1669302174171529e-08 0.008795106408101631 0.9999613223036531 3.1415900001026347
        children [
          DEF hip_joint Shape {
            appearance PBRAppearance {
              metalness 0
            }
            geometry Sphere {
              radius 0.05
            }
          }
          DEF leftLeftHorizintal1 HingeJoint {
            jointParameters HingeJointParameters {
              position -3.88273868718422e-06
              axis 0 0 1
              stopCFM 2
            }
            device [
              RotationalMotor {
                name "leftLegHorizontal1"
              }
            ]
            endPoint Solid {
              translation 0.007787267730122387 0.1410679697651369 0.11046199999999952
              rotation 0.6715224760784557 0.6587973375902673 -0.3391808250851383 2.562720120458999
              children [
                DEF thigh Shape {
                  appearance PBRAppearance {
                    metalness 0
                  }
                  geometry Cylinder {
                    height 0.3
                    radius 0.03
                  }
                }
                Solid {
                  translation -6.82356197588041e-05 -4.93965396133343e-05 -0.16039615067044916
                  rotation 1.6504199957195536e-05 0.9999999974064502 7.010499981817918e-05 -0.28961530717958617
                  children [
                    DEF knee Shape {
                      appearance PBRAppearance {
                        metalness 0
                      }
                      geometry Sphere {
                        radius 0.05
                      }
                    }
                    Solid {
                      translation 0.19485 0 -0.0142444
                      rotation 0 -1 0 1.5
                      children [
                        DEF leg Shape {
                          appearance PBRAppearance {
                            metalness 0
                          }
                          geometry Cylinder {
                            height 0.4
                            radius 0.03
                          }
                        }
                        Solid {
                          translation 0.000577156 0 -0.21211
                          rotation 0 1 0 0.58
                          children [
                            DEF foot Shape {
                              appearance PBRAppearance {
                                metalness 0
                              }
                              geometry Sphere {
                                radius 0.04
                              }
                            }
                          ]
                          boundingObject USE foot
                          physics DEF dog Physics {
                            mass 1
                          }
                        }
                      ]
                      boundingObject USE leg
                      physics USE dog
                    }
                  ]
                  boundingObject USE knee
                  physics USE dog
                }
              ]
              boundingObject USE thigh
              physics DEF dog Physics {
                mass 1
              }
              linearVelocity 7.736975046335537e-06 2.8922578542132995e-05 -3.33888254886575e-05
              angularVelocity -0.00028779037606739376 -6.18875521324048e-05 -0.00016416050119574945
            }
          }
        ]
        name "solid(1)"
        boundingObject USE hip_joint
        physics DEF dog Physics {
          mass 1
        }
        linearVelocity 6.0450534617699725e-05 1.146339668650854e-05 -0.00011923002630425452
        angularVelocity -0.00028799580229588065 -6.0018385841687045e-05 -2.2088258461727696e-06
      }
    }
    DEF rightLeg2 HingeJoint {
      jointParameters HingeJointParameters {
        position 0.9815362568653203
        anchor 0 -0.18 0
      }
      device [
        RotationalMotor {
          name "rightLegVertical1"
        }
      ]
      endPoint Solid {
        translation 0 -0.18 0
        rotation -1.2248625912856556e-08 0.009231740433081857 0.9999573865763361 3.1415900001130783
        children [
          DEF hip_joint Shape {
            appearance PBRAppearance {
              metalness 0
            }
            geometry Sphere {
              radius 0.05
            }
          }
          DEF leftLeftHorizintal1 HingeJoint {
            jointParameters HingeJointParameters {
              position -3.6785838451795604e-06
              axis 0 0 1
              stopCFM 2
            }
            device [
              RotationalMotor {
                name "leftLegHorizontal1"
              }
            ]
            endPoint Solid {
              translation 0.007787238930413149 0.14106797135494228 0.11046199999999955
              rotation 0.6715224157539216 0.6587974129301462 -0.33918079818374697 2.562720051213594
              children [
                DEF thigh Shape {
                  appearance PBRAppearance {
                    metalness 0
                  }
                  geometry Cylinder {
                    height 0.3
                    radius 0.03
                  }
                }
                Solid {
                  translation -6.82356197588041e-05 -4.93965396133343e-05 -0.16039615067044916
                  rotation 1.6504199957195536e-05 0.9999999974064502 7.010499981817918e-05 -0.28961530717958617
                  children [
                    DEF knee Shape {
                      appearance PBRAppearance {
                        metalness 0
                      }
                      geometry Sphere {
                        radius 0.05
                      }
                    }
                    Solid {
                      translation 0.19485 0 -0.0142444
                      rotation 0 -1 0 1.5
                      children [
                        DEF leg Shape {
                          appearance PBRAppearance {
                            metalness 0
                          }
                          geometry Cylinder {
                            height 0.4
                            radius 0.03
                          }
                        }
                        Solid {
                          translation 0.000577156 0 -0.21211
                          rotation 0 1 0 0.58
                          children [
                            DEF foot Shape {
                              appearance PBRAppearance {
                                metalness 0
                              }
                              geometry Sphere {
                                radius 0.04
                              }
                            }
                          ]
                          boundingObject USE foot
                          physics DEF dog Physics {
                            mass 1
                          }
                        }
                      ]
                      boundingObject USE leg
                      physics USE dog
                    }
                  ]
                  boundingObject USE knee
                  physics USE dog
                }
              ]
              boundingObject USE thigh
              physics DEF dog Physics {
                mass 1
              }
              linearVelocity 7.726265599806719e-06 3.1673417138108574e-05 -4.1481130612741845e-05
              angularVelocity -0.000322414025446742 -6.202306654909388e-05 -0.00016421199027828683
            }
          }
        ]
        name "solid(2)"
        boundingObject USE hip_joint
        physics DEF dog Physics {
          mass 1
        }
        linearVelocity 6.047364032145278e-05 1.2143608609008553e-05 -0.00013777762273361024
        angularVelocity -0.0003226194364742689 -6.0013624470389715e-05 -2.258316882886021e-06
      }
    }
    DEF rightLeg3 HingeJoint {
      jointParameters HingeJointParameters {
        position 0.980662248166114
        anchor -0.31 -0.18 0
      }
      device [
        RotationalMotor {
          name "rightLegVertical1"
        }
      ]
      endPoint Solid {
        translation -0.31 -0.18 0
        rotation -1.2828415164083539e-08 0.009668725265019067 0.9999532567834106 3.141590000124037
        children [
          DEF hip_joint Shape {
            appearance PBRAppearance {
              metalness 0
            }
            geometry Sphere {
              radius 0.05
            }
          }
          DEF leftLeftHorizintal1 HingeJoint {
            jointParameters HingeJointParameters {
              position -3.4732793510723836e-06
              axis 0 0 1
              stopCFM 2
            }
            device [
              RotationalMotor {
                name "leftLegHorizontal1"
              }
            ]
            endPoint Solid {
              translation 0.007787209968524494 0.14106797295369458 0.11046199999999956
              rotation 0.6715223550896753 0.6587974886942798 -0.33918077113086226 2.562719981578255
              children [
                DEF thigh Shape {
                  appearance PBRAppearance {
                    metalness 0
                  }
                  geometry Cylinder {
                    height 0.3
                    radius 0.03
                  }
                }
                Solid {
                  translation -6.82356197588041e-05 -4.93965396133343e-05 -0.16039615067044916
                  rotation 1.6504199957195536e-05 0.9999999974064502 7.010499981817918e-05 -0.28961530717958617
                  children [
                    DEF knee Shape {
                      appearance PBRAppearance {
                        metalness 0
                      }
                      geometry Sphere {
                        radius 0.05
                      }
                    }
                    Solid {
                      translation 0.19485 0 -0.0142444
                      rotation 0 -1 0 1.5
                      children [
                        DEF leg Shape {
                          appearance PBRAppearance {
                            metalness 0
                          }
                          geometry Cylinder {
                            height 0.4
                            radius 0.03
                          }
                        }
                        Solid {
                          translation 0.000577156 0 -0.21211
                          rotation 0 1 0 0.58
                          children [
                            DEF foot Shape {
                              appearance PBRAppearance {
                                metalness 0
                              }
                              geometry Sphere {
                                radius 0.04
                              }
                            }
                          ]
                          boundingObject USE foot
                          physics DEF dog Physics {
                            mass 1
                          }
                        }
                      ]
                      boundingObject USE leg
                      physics USE dog
                    }
                  ]
                  boundingObject USE knee
                  physics USE dog
                }
              ]
              boundingObject USE thigh
              physics DEF dog Physics {
                mass 1
              }
              linearVelocity 7.715612052963677e-06 3.444184856304843e-05 -4.958854461040578e-05
              angularVelocity -0.0003569982693600586 -6.215872406091746e-05 -0.00016426348118761216
            }
          }
        ]
        name "solid(3)"
        boundingObject USE hip_joint
        physics DEF dog Physics {
          mass 1
        }
        linearVelocity 6.049679460943664e-05 1.2824573393999109e-05 -0.0001563251569420397
        angularVelocity -0.0003572036654304602 -6.000887741541861e-05 -2.3077389304515502e-06
      }
    }
    DEF leftLeg1 HingeJoint {
      jointParameters HingeJointParameters {
        position 1.0000301474081221
        anchor 0.31 0.18 0
      }
      device [
        RotationalMotor {
          name "leftLegVertical1"
          maxTorque 50
        }
      ]
      endPoint Solid {
        translation 0.31 0.18 0
        rotation 0.9848569160549505 2.6133309128049222e-06 -0.17336912900485676 3.0610960411871816e-05
        children [
          DEF hip_joint Shape {
            appearance PBRAppearance {
              metalness 0
            }
            geometry Sphere {
              radius 0.05
            }
          }
          DEF leftLeftHorizintal1 HingeJoint {
            jointParameters HingeJointParameters {
              position 3.068940928055685e-05
              axis 0 0 1
              stopCFM 2
            }
            device [
              RotationalMotor {
                name "leftLegHorizontal1"
              }
            ]
            endPoint Solid {
              translation 0.007782390702745326 0.14106823890340436 0.11046199999999948
              rotation 0.6715122604404783 0.6588100957825255 -0.33917626947228896 2.562708394328074
              children [
                DEF thigh Shape {
                  appearance PBRAppearance {
                    metalness 0
                  }
                  geometry Cylinder {
                    height 0.3
                    radius 0.03
                  }
                }
                Solid {
                  translation -6.82356197588041e-05 -4.93965396133343e-05 -0.16039615067044916
                  rotation 1.6504199957195536e-05 0.9999999974064502 7.010499981817918e-05 -0.28961530717958617
                  children [
                    DEF knee Shape {
                      appearance PBRAppearance {
                        metalness 0
                      }
                      geometry Sphere {
                        radius 0.05
                      }
                    }
                    Solid {
                      translation 0.19485 0 -0.0142444
                      rotation 0 -1 0 1.5
                      children [
                        DEF leg Shape {
                          appearance PBRAppearance {
                            metalness 0
                          }
                          geometry Cylinder {
                            height 0.4
                            radius 0.03
                          }
                        }
                        Solid {
                          translation 0.000577156 0 -0.21211
                          rotation 0 1 0 0.58
                          children [
                            DEF foot Shape {
                              appearance PBRAppearance {
                                metalness 0
                              }
                              geometry Sphere {
                                radius 0.04
                              }
                            }
                          ]
                          boundingObject USE foot
                          physics DEF dog Physics {
                            mass 1
                          }
                        }
                      ]
                      boundingObject USE leg
                      physics USE dog
                    }
                  ]
                  boundingObject USE knee
                  physics USE dog
                }
              ]
              boundingObject USE thigh
              physics DEF dog Physics {
                mass 1
              }
              linearVelocity 9.635066463710144e-06 4.018042590704584e-06 -3.7308777527287972e-06
              angularVelocity 0.00017388106482029377 -6.121966807600231e-05 0.00016169768763496807
            }
          }
        ]
        name "solid(4)"
        boundingObject USE hip_joint
        physics DEF dog Physics {
          mass 1
        }
        linearVelocity 6.120820157009502e-05 1.1216941775728631e-05 -5.664846597193051e-05
        angularVelocity 0.0001741369564456364 -6.012639824815043e-05 -1.7703388555667663e-06
      }
    }
    DEF leftLeg2 HingeJoint {
      jointParameters HingeJointParameters {
        position 1.0012101293723543
        anchor 0 0.18 0
      }
      device [
        RotationalMotor {
          name "rightLegVertical1"
        }
      ]
      endPoint Solid {
        translation 0 0.18 0
        rotation 0.9999903839514527 2.653469644185569e-06 -0.004385430148309172 0.001210141009080925
        children [
          DEF hip_joint Shape {
            appearance PBRAppearance {
              metalness 0
            }
            geometry Sphere {
              radius 0.05
            }
          }
          DEF leftLeftHorizintal1 HingeJoint {
            jointParameters HingeJointParameters {
              position 2.77634832042154e-05
              axis 0 0 1
              stopCFM 2
            }
            device [
              RotationalMotor {
                name "leftLegHorizontal1"
              }
            ]
            endPoint Solid {
              translation 0.007782803457950763 0.14106821613210066 0.11046199999999956
              rotation 0.6715131250239641 0.6588090160308963 -0.33917665502942906 2.5627093867333297
              children [
                DEF thigh Shape {
                  appearance PBRAppearance {
                    metalness 0
                  }
                  geometry Cylinder {
                    height 0.3
                    radius 0.03
                  }
                }
                Solid {
                  translation -6.82356197588041e-05 -4.93965396133343e-05 -0.16039615067044916
                  rotation 1.6504199957195536e-05 0.9999999974064502 7.010499981817918e-05 -0.28961530717958617
                  children [
                    DEF knee Shape {
                      appearance PBRAppearance {
                        metalness 0
                      }
                      geometry Sphere {
                        radius 0.05
                      }
                    }
                    Solid {
                      translation 0.19485 0 -0.0142444
                      rotation 0 -1 0 1.5
                      children [
                        DEF leg Shape {
                          appearance PBRAppearance {
                            metalness 0
                          }
                          geometry Cylinder {
                            height 0.4
                            radius 0.03
                          }
                        }
                        Solid {
                          translation 0.000577156 0 -0.21211
                          rotation 0 1 0 0.58
                          children [
                            DEF foot Shape {
                              appearance PBRAppearance {
                                metalness 0
                              }
                              geometry Sphere {
                                radius 0.04
                              }
                            }
                          ]
                          boundingObject USE foot
                          physics DEF dog Physics {
                            mass 1
                          }
                        }
                      ]
                      boundingObject USE leg
                      physics USE dog
                    }
                  ]
                  boundingObject USE knee
                  physics USE dog
                }
              ]
              boundingObject USE thigh
              physics DEF dog Physics {
                mass 1
              }
              linearVelocity 9.654163162817417e-06 4.514954542699455e-06 -2.1876625700604005e-05
              angularVelocity 0.00017406192496039908 -6.115440799366506e-05 0.00015772526161408922
            }
          }
        ]
        name "solid(5)"
        boundingObject USE hip_joint
        physics DEF dog Physics {
          mass 1
        }
        linearVelocity 6.063679123578317e-05 1.1809411287330814e-05 -7.504368876988468e-05
        angularVelocity 0.00017421918443005807 -6.0013837861028194e-05 -1.5027740817852319e-06
      }
    }
    DEF leftLeg3 HingeJoint {
      jointParameters HingeJointParameters {
        position 1.0019895354778106
        anchor -0.31 0.18 0
      }
      device [
        RotationalMotor {
          name "rightLegVertical1"
        }
      ]
      endPoint Solid {
        translation -0.31 0.18 0
        rotation 0.9999964423689008 2.6534855619300618e-06 -0.0026674411897334364 0.001989542555716315
        children [
          DEF hip_joint Shape {
            appearance PBRAppearance {
              metalness 0
            }
            geometry Sphere {
              radius 0.05
            }
          }
          DEF leftLeftHorizintal1 HingeJoint {
            jointParameters HingeJointParameters {
              position 2.8003347713527194e-05
              axis 0 0 1
              stopCFM 2
            }
            device [
              RotationalMotor {
                name "leftLegHorizontal1"
              }
            ]
            endPoint Solid {
              translation 0.007782769620692092 0.14106821799891486 0.11046199999999937
              rotation 0.6715130541463317 0.6588091045478998 -0.3391766234218689 2.562709305376892
              children [
                DEF thigh Shape {
                  appearance PBRAppearance {
                    metalness 0
                  }
                  geometry Cylinder {
                    height 0.3
                    radius 0.03
                  }
                }
                Solid {
                  translation -6.82356197588041e-05 -4.93965396133343e-05 -0.16039615067044916
                  rotation 1.6504199957195536e-05 0.9999999974064502 7.010499981817918e-05 -0.28961530717958617
                  children [
                    DEF knee Shape {
                      appearance PBRAppearance {
                        metalness 0
                      }
                      geometry Sphere {
                        radius 0.05
                      }
                    }
                    Solid {
                      translation 0.19485 0 -0.0142444
                      rotation 0 -1 0 1.5
                      children [
                        DEF leg Shape {
                          appearance PBRAppearance {
                            metalness 0
                          }
                          geometry Cylinder {
                            height 0.4
                            radius 0.03
                          }
                        }
                        Solid {
                          translation 0.000577156 0 -0.21211
                          rotation 0 1 0 0.58
                          children [
                            DEF foot Shape {
                              appearance PBRAppearance {
                                metalness 0
                              }
                              geometry Sphere {
                                radius 0.04
                              }
                            }
                          ]
                          boundingObject USE foot
                          physics DEF dog Physics {
                            mass 1
                          }
                        }
                      ]
                      boundingObject USE leg
                      physics USE dog
                    }
                  ]
                  boundingObject USE knee
                  physics USE dog
                }
              ]
              boundingObject USE thigh
              physics DEF dog Physics {
                mass 1
              }
              linearVelocity 9.647617164114882e-06 3.1240047819061164e-06 -3.500951409796843e-05
              angularVelocity 0.00019138112724762825 -6.144931341660312e-05 0.000160247589147701
            }
          }
        ]
        name "solid(6)"
        boundingObject USE hip_joint
        physics DEF dog Physics {
          mass 1
        }
        linearVelocity 6.103763573626926e-05 1.1866447996524698e-05 -9.351623288886912e-05
        angularVelocity 0.00019158679549491405 -6.0088662186763645e-05 -1.6514995070104962e-06
      }
    }
  ]
  boundingObject USE base_torso
  physics DEF dog Physics {
    mass 1
  }
  controller ""
  linearVelocity 6.070964429545353e-05 1.1887556714540901e-05 -0.00010642702951434902
  angularVelocity 0.00017417883520042738 -6.0046855011516856e-05 -1.602860531675645e-06
}
Forest {
  density 0.08
}
Floor {
  translation 0 0 -0.01
}
